Workbook

Sheet Sales_Data
A1: Order_ID | B1: Order_Date | C1: Customer_Name | D1: Product | E1: Category | F1: Quantity | G1: Unit_Price | H1: Sales_Amount | I1: Region
A2: 1001 | B2: 2024-01-02 | C2: Ayaan Khan | D2: Laptop | E2: Electronics | F2: 1 | G2: 800 | H2: 800 | I2: Asia
A3: 1002 | B3: 2024-01-03 | C3: Sara Ali | D3: Mouse | E3: Electronics | F3: 2 | G3: 20 | H3: 40 | I3: Europe
A4: 1003 | B4: 2024-01-05 | C4: John Smith | D4: Desk | E4: Furniture | F4: 1 | G4: 150 | H4: 150 | I4: USA
A5: 1004 | B5: 2024-01-06 | C5: Nina Roy | D5: Chair | E5: Furniture | F5: 4 | G5: 75 | H5: 300 | I5: Asia
A6: 1005 | B6: 2024-01-08 | C6: Omar Faruk | D6: Keyboard | E6: Electronics | F6: 3 | G6: 30 | H6: 90 | I6: Asia
A7: 1006 | B7: 2024-01-10 | C7: Liam Brown | D7: Monitor | E7: Electronics | F7: 2 | G7: 200 | H7: 400 | I7: Europe
A8: 1007 | B8: 2024-01-12 | C8: Sophia Lee | D8: Table | E8: Furniture | F8: 1 | G8: 250 | H8: 250 | I8: USA
A9: 1008 | B9: 2024-01-14 | C9: Arif Hasan | D9: Mouse | E9: Electronics | F9: 5 | G9: 20 | H9: 100 | I9: Asia
A10: 1009 | B10: 2024-01-15 | C10: Emma Wilson | D10: Chair | E10: Furniture | F10: 2 | G10: 75 | H10: 150 | I10: Europe
A11: 1010 | B11: 2024-01-18 | C11: Noah Kim | D11: Laptop | E11: Electronics | F11: 1 | G11: 820 | H11: 820 | I11: USA

Sheet formula_work
A1: **Formula-Based Approach**
A4: 1. Calculate total sales revenue.
B5: Sales Revenue
B6: =SUM(Sales_Data!H2:H11) -> 3100
A9: 2. Find average sales amount per order.
B10: Average
B11: =AVERAGE(Sales_Data!H2:H11) -> 310
A14: 3. Count total number of orders.
B15: Count Total order
B16: =COUNT(Sales_Data!A2:A11) -> 10
A18: 4. Find total quantity sold per product.
B19: Total Quantity Sold
B20: {=_xlfn.UNIQUE(Sales_Data!D2:D11)} -> Laptop | C20: =SUMIF(Sales_Data!D2:D11,formula_work!B20,Sales_Data!F2:F11) -> 2
B21: Mouse | C21: =SUMIF(Sales_Data!D3:D12,formula_work!B21,Sales_Data!F3:F12) -> 7
B22: Desk | C22: =SUMIF(Sales_Data!D4:D13,formula_work!B22,Sales_Data!F4:F13) -> 1
B23: Chair | C23: =SUMIF(Sales_Data!D5:D14,formula_work!B23,Sales_Data!F5:F14) -> 6
B24: Keyboard | C24: =SUMIF(Sales_Data!D6:D15,formula_work!B24,Sales_Data!F6:F15) -> 3
B25: Monitor | C25: =SUMIF(Sales_Data!D7:D16,formula_work!B25,Sales_Data!F7:F16) -> 2
B26: Table | C26: =SUMIF(Sales_Data!D8:D17,formula_work!B26,Sales_Data!F8:F17) -> 1
A28: 5. Identify the highest selling product by sales amount.
B29: Product | C29: Sales Amount
B30: {=_xlfn._xlws.SORT(_xlfn.HSTACK(_xlfn.UNIQUE(Sales_Data!D2:D11),_xlfn.BYROW(_xlfn.UNIQUE(Sales_Data!D2:D11),_xlfn.LAMBDA(_xlpm.p,SUMIF(Sales_Data!D2:D11,_xlpm.p,Sales_Data!H2:H11)))),2,-1,FALSE)} -> Laptop | C30: 1620
B31: Chair | C31: 450
B32: Monitor | C32: 400
B33: Table | C33: 250
B34: Desk | C34: 150
B35: Mouse | C35: 140
B36: Keyboard | C36: 90
A39: 6. Calculate total sales by category.
B40: Category | C40: Total Sales
B41: {=_xlfn.UNIQUE(Sales_Data!E2:E11)} -> Electronics | C41: =SUMIF(Sales_Data!E2:E11,formula_work!B41,Sales_Data!$H$2:$H$11) -> 2250
B42: Furniture | C42: =SUMIF(Sales_Data!E3:E12,formula_work!B42,Sales_Data!$H$2:$H$11) -> 690
A45: 7. Find total sales by region.
B46: Region | C46: Total Sales
B47: {=_xlfn.UNIQUE(Sales_Data!I2:I11)} -> Asia | C47: =SUMIF(Sales_Data!I2:I11,formula_work!B47,Sales_Data!H2:H11) -> 1290
B48: Europe | C48: =SUMIF(Sales_Data!I3:I12,formula_work!B48,Sales_Data!H3:H12) -> 590
B49: USA | C49: =SUMIF(Sales_Data!I4:I13,formula_work!B49,Sales_Data!H4:H13) -> 1220
A52: 8. Identify the order with the highest sales amount.
B53: Order_ID | C53: Order_Date | D53: Customer_Name | E53: Product | F53: Category | G53: Quantity | H53: Unit_Price | I53: Sales_Amount | J53: Region
B54: {=_xlfn.XLOOKUP(MAX(Sales_Data!A2:A11),Sales_Data!A2:A11,Sales_Data!A2:I11)} -> 1010 | C54: 2024-01-18 | D54: Noah Kim | E54: Laptop | F54: Electronics | G54: 1 | H54: 820 | I54: 820 | J54: USA
...
